# SwiftCompilationError(error: call can throw, but it is not marked with 'try')

let a = A()

let result = a.foo()

exit(result)
